<?xml version="1.0" ?>
<robot name="robotiq_hande_gripper">
  <!--
    Original URDF file by Cristian C Beltran-Hernandez
  -->
  <link name="tool0"/>
  <!-- Robotiq Hand-E specs -->
  <!--  + Height added by the IO coupler: 11.0mm -->
  <!--  + Height added by the Hand-E: 99.0mm -->
  <!--  + Coupler mass includes the bolts -->
  <joint name="robotiq_hande_coupler_joint" type="fixed">
    <origin rpy="0 0 0" xyz="0 0 0"/>
    <parent link="tool0"/>
    <child link="robotiq_hande_coupler"/>
  </joint>
  <link name="robotiq_hande_coupler">
    <visual>
      <geometry>
        <mesh filename="package://robotiq_hande_description/meshes/io_coupler.dae"/>
      </geometry>
    </visual>
    <collision>
      <origin rpy="0 0 0" xyz="0 0 0.005449999999999999"/>
      <geometry>
        <cylinder length="0.0169" radius="0.0385"/>
      </geometry>
    </collision>
    <inertial>
      <mass value="0.119"/>
      <origin rpy="0 0 0" xyz="0 0 0.005449999999999999"/>
      <inertia ixx="4.4668218799372e-05" ixy="0.0" ixz="0.0" iyy="4.4668218799372e-05" iyz="0.0" izz="8.367187499999999e-05"/>
    </inertial>
  </link>
  <joint name="robotiq_hande_base_joint" type="fixed">
    <origin rpy="0 0 0" xyz="0 0 0.011"/>
    <parent link="robotiq_hande_coupler"/>
    <child link="robotiq_hande_link"/>
  </joint>
  <link name="robotiq_hande_link">
    <visual>
      <origin rpy="0 0 0" xyz="0 0 0"/>
      <geometry>
        <mesh filename="package://robotiq_hande_description/meshes/hande.dae" scale="1.0 1.0 1.0"/>
      </geometry>
    </visual>
    <collision>
      <origin rpy="0 0 0" xyz="0 0 0.053450000000000004"/>
      <geometry>
        <cylinder length="0.10690000000000001" radius="0.0385"/>
      </geometry>
    </collision>
    <inertial>
      <mass value="0.86387"/>
      <origin rpy="0 0 0" xyz="0 0 0.0495"/>
      <inertia ixx="0.0010092697156669523" ixy="0.0" ixz="0.0" iyy="0.0010092697156669523" iyz="0.0" izz="0.00060740859375"/>
    </inertial>
  </link>
  <joint name="robotiq_hande_left_finger_joint" type="prismatic">
    <origin rpy="0 0 0" xyz="0 0 0.099"/>
    <parent link="robotiq_hande_link"/>
    <child link="robotiq_hande_left_finger"/>
    <axis xyz="1 0 0"/>
    <limit effort="130" lower="0" upper="0.025" velocity="0.15"/>
  </joint>
  <link name="robotiq_hande_left_finger">
    <visual>
      <origin rpy="0 0 0" xyz="0 0 0"/>
      <geometry>
        <mesh filename="package://robotiq_hande_description/meshes/finger.dae" scale="1.0 1.0 1.0"/>
      </geometry>
    </visual>
    <collision>
      <origin rpy="0 0 0" xyz="0 0 0"/>
      <geometry>
        <mesh filename="package://robotiq_hande_description/meshes/finger_collision.dae" scale="1.0 1.0 1.0"/>
      </geometry>
    </collision>
    <inertial>
      <origin rpy="0 0 0" xyz="0 0 0"/>
      <mass value="0.03804"/>
      <inertia ixx="1E-9" ixy="0.0" ixz="0.0" iyy="1E-9" iyz="0.0" izz="1E-9"/>
    </inertial>
  </link>
  <joint name="robotiq_hande_right_finger_joint" type="prismatic">
    <origin rpy="0 0 0" xyz="0 0 0.099"/>
    <parent link="robotiq_hande_link"/>
    <child link="robotiq_hande_right_finger"/>
    <axis xyz="-1 0 0"/>
    <limit effort="130" lower="0" upper="0.025" velocity="0.15"/>
    <mimic joint="robotiq_hande_left_finger_joint" multiplier="1" offset="0"/>
  </joint>
  <link name="robotiq_hande_right_finger">
    <visual>
      <origin rpy="0 0 3.141592653589793" xyz="0 0 0"/>
      <geometry>
        <mesh filename="package://robotiq_hande_description/meshes/finger.dae" scale="1.0 1.0 1.0"/>
      </geometry>
    </visual>
    <collision>
      <origin rpy="0 0 3.141592653589793" xyz="0 0 0"/>
      <geometry>
        <mesh filename="package://robotiq_hande_description/meshes/finger_collision.dae" scale="1.0 1.0 1.0"/>
      </geometry>
    </collision>
    <inertial>
      <origin rpy="0 0 0" xyz="0 0 0"/>
      <mass value="0.03804"/>
      <inertia ixx="1E-9" ixy="0.0" ixz="0.0" iyy="1E-9" iyz="0.0" izz="1E-9"/>
    </inertial>
  </link>
  <joint name="robotiq_hande_end_joint" type="fixed">
    <origin rpy="0 0 0" xyz="0 0 0.14550000000000002"/>
    <parent link="robotiq_hande_link"/>
    <child link="robotiq_hande_end"/>
  </joint>
  <link name="robotiq_hande_end"/>
</robot>
